#VRML_SIM R2021a utf8
WorldInfo {
  basicTimeStep 16
  coordinateSystem "NUE"
  contactProperties [
    ContactProperties {
      material2 "slippy"
      coulombFriction [
        0
      ]
    }
    ContactProperties {
      material2 "block"
      coulombFriction [
        0.01
      ]
    }
  ]
}
Viewpoint {
  orientation 1 0 0 4.71238898038469
  position -1.9765126844225015e-15 3.7929556675363383 -2.085115520971619e-15
}
TexturedBackground {
}
TexturedBackgroundLight {
}
Floor {
  size 2.4 2.4
  appearance Asphalt {
  }
}
DEF Block_R1 Solid {
  translation -0.0285929 0.05 0.758097
  children [
    DEF BOX_R Shape {
      appearance PBRAppearance {
        baseColor 1 0 0
        metalness 0
      }
      geometry Box {
        size 0.05 0.05 0.05
      }
    }
  ]
  name "solid(4)"
  boundingObject USE BOX_R
  physics Physics {
  }
}
DEF Block_R2 Solid {
  translation -0.496302 0.05 -0.427039
  children [
    USE BOX_R
  ]
  name "solid(13)"
  boundingObject USE BOX_R
  physics Physics {
  }
}
DEF Block_R3 Solid {
  translation -0.557086 0.0249755 -0.95098
  rotation 0 0 1 3.14159
  children [
    USE BOX_R
  ]
  name "solid(12)"
  boundingObject USE BOX_R
  physics Physics {
  }
}
DEF Block_R4 Solid {
  translation -0.996281 0.05 -0.033488
  rotation 0 0 1 4.692820414042842e-06
  children [
    USE BOX_R
  ]
  name "solid(7)"
  boundingObject USE BOX_R
  physics Physics {
  }
}
DEF Block_B1 Solid {
  translation 1.10866 0.05 -0.140758
  children [
    DEF BOX_B Shape {
      appearance PBRAppearance {
        baseColor 0 0 1
        metalness 0
      }
      geometry Box {
        size 0.05 0.05 0.05
      }
    }
  ]
  name "solid(8)"
  boundingObject USE BOX_B
  physics Physics {
  }
}
DEF Block_B2 Solid {
  translation 0.591246 0.05 0.0911656
  children [
    USE BOX_B
  ]
  name "solid(9)"
  boundingObject USE BOX_B
  physics Physics {
  }
}
DEF Block_B3 Solid {
  translation -0.368188 0.05 0.492528
  children [
    USE BOX_B
  ]
  name "solid(10)"
  boundingObject USE BOX_B
  physics Physics {
  }
}
DEF Block_B4 Solid {
  translation -0.0450972 0.05 -0.894944
  children [
    USE BOX_B
  ]
  name "solid(11)"
  boundingObject USE BOX_B
  physics Physics {
  }
}
DEF Floor_colour Solid {
  translation 1 0.0001 1
  children [
    Shape {
      appearance PBRAppearance {
        baseColor 1 0 0
      }
      geometry Plane {
        size 0.4 0.4
      }
    }
  ]
  name "solid(6)"
}
DEF Floor_colour Solid {
  translation 1 0.0001 -1
  children [
    Shape {
      appearance PBRAppearance {
        baseColor 0 0 1
      }
      geometry Plane {
        size 0.4 0.4
      }
    }
  ]
  name "solid(5)"
}
DEF WALL_1 Solid {
  translation 1.2 0.05 0
  children [
    DEF WALL_SHAPE Shape {
      appearance PBRAppearance {
        baseColor 0 0.333333 0
        roughness 1
        metalness 0
      }
      geometry Box {
        size 0.02 0.1 2.38
      }
    }
  ]
  boundingObject USE WALL_SHAPE
}
DEF WALL_2 Solid {
  translation -1.2 0.05 0
  children [
    USE WALL_SHAPE
  ]
  name "solid(1)"
  boundingObject USE WALL_SHAPE
}
DEF WALL_3 Solid {
  translation 0 0.05 -1.2
  rotation 0 1 0 1.5708
  children [
    USE WALL_SHAPE
  ]
  name "solid(2)"
  boundingObject USE WALL_SHAPE
}
DEF WALL_4 Solid {
  translation 0 0.05 1.2
  rotation 0 1 0 1.5708
  children [
    USE WALL_SHAPE
  ]
  name "solid(3)"
  boundingObject USE WALL_SHAPE
}
Robot {
  translation 0.95 0.052 0.95
  children [
    GPS {
      name "gps_mid"
    }
    DEF DS_MID DistanceSensor {
      translation 0 -0.01 0.1
      rotation 0 1 0 -1.5708003061004252
      children [
        DEF DS_box_shape Shape {
          appearance PBRAppearance {
            baseColor 0.639 0.757 0.678
            roughness 1
            metalness 0
          }
          geometry Box {
            size 0.01 0.01 0.01
          }
        }
      ]
      name "ds_mid"
      lookupTable [
        0 1400 0
        0.01 1390 0.01
        1.4 0 0
      ]
    }
    DEF Arm1 HingeJoint {
      jointParameters HingeJointParameters {
        axis 0 0 -1
        anchor 0.05 0 0.1
      }
      device [
        RotationalMotor {
          name "arm_1"
          maxTorque 0.35
        }
      ]
      endPoint DEF Arm_1 Solid {
        translation 0.0500000000000281 -9.110891234509485e-08 0.12499999981728238
        rotation 0 0 -1 0
        children [
          Solid {
            translation 0 -0.016 0.01
            children [
              DEF arm2 Shape {
                appearance PBRAppearance {
                  baseColor 0.639 0.757 0.678
                  roughness 1
                  metalness 0
                }
                geometry Box {
                  size 0.01 0.022 0.03
                }
              }
            ]
            boundingObject USE arm2
            physics Physics {
            }
          }
          DEF arm1 Shape {
            appearance PBRAppearance {
              baseColor 0.639 0.757 0.678
              roughness 1
              metalness 0
            }
            geometry Box {
              size 0.01 0.01 0.05
            }
          }
        ]
        name "solid(6)"
        boundingObject USE arm1
        physics Physics {
        }
      }
    }
    DEF Arm2 HingeJoint {
      jointParameters HingeJointParameters {
        axis 0 0 1
        anchor -0.05 0 0.1
      }
      device [
        RotationalMotor {
          name "arm_2"
          maxTorque 0.35
        }
      ]
      endPoint DEF Arm_1 Solid {
        translation -0.04999999999999879 -9.110897587066846e-08 0.12499999981728249
        rotation 0 0 1 0
        children [
          USE arm1
          Solid {
            translation 0 -0.016 0.01
            children [
              USE arm2
            ]
            boundingObject USE arm2
            physics Physics {
            }
          }
        ]
        name "solid(5)"
        boundingObject USE arm1
        physics Physics {
        }
      }
    }
    Receiver {
    }
    Emitter {
    }
    GPS {
      translation 0 0 0.1
      name "gps_front"
    }
    DEF Wheel1 HingeJoint {
      jointParameters HingeJointParameters {
        anchor 0.09 0 0
      }
      device [
        RotationalMotor {
          name "wheel1"
          maxTorque 0.15
        }
      ]
      endPoint Solid {
        translation 0.09000000376666334 -3.860335181469741e-06 2.1725002220855488e-07
        rotation 0.004720662955283152 -0.004720680628829172 -0.9999777150095213 4.712363021520027
        children [
          DEF WHEEL_SHAPE Shape {
            appearance PBRAppearance {
              baseColor 0.639 0.757 0.678
              roughness 1
              metalness 0
            }
            geometry Cylinder {
              height 0.02
              radius 0.05
              subdivision 24
            }
          }
        ]
        name "solid(3)"
        boundingObject USE WHEEL_SHAPE
        physics Physics {
        }
      }
    }
    DEF Wheel2 HingeJoint {
      jointParameters HingeJointParameters {
        anchor -0.09 0 0
      }
      device [
        RotationalMotor {
          name "wheel2"
          maxTorque 0.15
        }
      ]
      endPoint Solid {
        translation -0.09000000376665324 3.5547451195393113e-06 -1.5209282810666182e-06
        rotation 0.004186231954784659 -0.0041862474088153485 -0.999982475243768 4.712367782087172
        children [
          USE WHEEL_SHAPE
        ]
        name "solid(1)"
        boundingObject USE WHEEL_SHAPE
        physics Physics {
        }
      }
    }
    DEF BALL_FRONT Solid {
      translation 0 -0.032 0.08
      children [
        DEF ROLLER_BALL Shape {
          geometry Sphere {
            radius 0.018
            subdivision 3
          }
        }
      ]
      name "solid(4)"
      contactMaterial "slippy"
      boundingObject USE ROLLER_BALL
      physics Physics {
        density -1
        mass 1
      }
    }
    DEF Camera1 Camera {
      translation 0 0 0.1
      rotation 0 1 0 3.14
      children [
        Shape {
          appearance PBRAppearance {
            baseColor 0 0 0
            roughness 1
            metalness 0
          }
          geometry Box {
            size 0.005 0.005 0.005
          }
        }
      ]
      name "camera1"
      recognitionColors [
        1 0 0
      ]
      fieldOfView 0.1
      width 1
      height 1
      near 0.002
      far 0.1
    }
    DEF BODY_SOLID Solid {
      children [
        DEF BODY_SHAPE Shape {
          appearance PBRAppearance {
            baseColor 1 0.1 0.1
            roughness 1
            metalness 0
          }
          geometry Box {
            size 0.16 0.05 0.2
          }
        }
      ]
    }
  ]
  name "My_Robot(1)"
  boundingObject USE BODY_SHAPE
  physics Physics {
    density -1
    mass 1
  }
  controller "main"
}
Robot {
  translation 0.95 0.052 -0.95
  rotation 0 1 0 3.14
  children [
    GPS {
      name "gps_mid"
    }
    DEF DS_MID DistanceSensor {
      translation 0 -0.01 0.1
      rotation 0 1 0 -1.5708003061004252
      children [
        DEF DS_box_shape Shape {
          appearance PBRAppearance {
            baseColor 0.639 0.757 0.678
            roughness 1
            metalness 0
          }
          geometry Box {
            size 0.01 0.01 0.01
          }
        }
      ]
      name "ds_mid"
      lookupTable [
        0 1400 0
        0.01 1390 0.01
        1.4 0 0
      ]
    }
    DEF Arm1 HingeJoint {
      jointParameters HingeJointParameters {
        axis 0 0 -1
        anchor 0.05 0 0.1
      }
      device [
        RotationalMotor {
          name "arm_1"
          maxTorque 0.35
        }
      ]
      endPoint DEF Arm_1 Solid {
        translation 0.0500000000000281 -9.110891234509485e-08 0.12499999981728238
        rotation 0 0 -1 0
        children [
          Solid {
            translation 0 -0.016 0.01
            children [
              DEF arm2 Shape {
                appearance PBRAppearance {
                  baseColor 0.639 0.757 0.678
                  roughness 1
                  metalness 0
                }
                geometry Box {
                  size 0.01 0.022 0.03
                }
              }
            ]
            boundingObject USE arm2
            physics Physics {
            }
          }
          DEF arm1 Shape {
            appearance PBRAppearance {
              baseColor 0.639 0.757 0.678
              roughness 1
              metalness 0
            }
            geometry Box {
              size 0.01 0.01 0.05
            }
          }
        ]
        name "solid(6)"
        boundingObject USE arm1
        physics Physics {
        }
      }
    }
    DEF Arm2 HingeJoint {
      jointParameters HingeJointParameters {
        axis 0 0 1
        anchor -0.05 0 0.1
      }
      device [
        RotationalMotor {
          name "arm_2"
          maxTorque 0.35
        }
      ]
      endPoint DEF Arm_1 Solid {
        translation -0.04999999999999879 -9.110897587066846e-08 0.12499999981728249
        rotation 0 0 1 0
        children [
          USE arm1
          Solid {
            translation 0 -0.016 0.01
            children [
              USE arm2
            ]
            boundingObject USE arm2
            physics Physics {
            }
          }
        ]
        name "solid(5)"
        boundingObject USE arm1
        physics Physics {
        }
      }
    }
    Receiver {
    }
    Emitter {
    }
    GPS {
      translation 0 0 0.1
      name "gps_front"
    }
    DEF Wheel1 HingeJoint {
      jointParameters HingeJointParameters {
        anchor 0.09 0 0
      }
      device [
        RotationalMotor {
          name "wheel1"
          maxTorque 0.15
        }
      ]
      endPoint Solid {
        translation 0.09000000376666334 -3.860335181469741e-06 2.1725002220855488e-07
        rotation 0.004720662955283152 -0.004720680628829172 -0.9999777150095213 4.712363021520027
        children [
          DEF WHEEL_SHAPE Shape {
            appearance PBRAppearance {
              baseColor 0.639 0.757 0.678
              roughness 1
              metalness 0
            }
            geometry Cylinder {
              height 0.02
              radius 0.05
              subdivision 24
            }
          }
        ]
        name "solid(3)"
        boundingObject USE WHEEL_SHAPE
        physics Physics {
        }
      }
    }
    DEF Wheel2 HingeJoint {
      jointParameters HingeJointParameters {
        anchor -0.09 0 0
      }
      device [
        RotationalMotor {
          name "wheel2"
          maxTorque 0.15
        }
      ]
      endPoint Solid {
        translation -0.09000000376665324 3.5547451195393113e-06 -1.5209282810666182e-06
        rotation 0.004186231954784659 -0.0041862474088153485 -0.999982475243768 4.712367782087172
        children [
          USE WHEEL_SHAPE
        ]
        name "solid(1)"
        boundingObject USE WHEEL_SHAPE
        physics Physics {
        }
      }
    }
    DEF BALL_FRONT Solid {
      translation 0 -0.032 0.08
      children [
        DEF ROLLER_BALL Shape {
          geometry Sphere {
            radius 0.018
            subdivision 3
          }
        }
      ]
      name "solid(4)"
      contactMaterial "slippy"
      boundingObject USE ROLLER_BALL
      physics Physics {
        density -1
        mass 1
      }
    }
    DEF Camera1 Camera {
      translation 0 0 0.1
      rotation 0 1 0 3.14
      children [
        Shape {
          appearance PBRAppearance {
            baseColor 0 0 0
            roughness 1
            metalness 0
          }
          geometry Box {
            size 0.005 0.005 0.005
          }
        }
      ]
      name "camera1"
      recognitionColors [
        1 0 0
      ]
      fieldOfView 0.1
      width 1
      height 1
      near 0.002
      far 0.1
    }
    DEF BODY_SOLID Solid {
      children [
        DEF BODY_SHAPE Shape {
          appearance PBRAppearance {
            baseColor 0.1 0.1 1
            roughness 1
            metalness 0
          }
          geometry Box {
            size 0.16 0.05 0.2
          }
        }
      ]
    }
  ]
  name "My_Robot"
  boundingObject USE BODY_SHAPE
  physics Physics {
    density -1
    mass 1
  }
  controller "main - Blue"
}
